2025-06-16 12:53:50.886 WARNING (MainThread) [homeassistant.bootstrap] Waiting on integrations to complete setup: {('wyoming', '01JWQ5X3ACXZT0RBZMC38WZ5RP'): 267085.303724634, ('wyoming', '01JWQ6F1KXK1SBB0NVY8S53WCP'): 267085.304627126}
2025-06-16 12:54:50.973 WARNING (MainThread) [homeassistant.bootstrap] Waiting on integrations to complete setup: {('wyoming', '01JWQ5X3ACXZT0RBZMC38WZ5RP'): 267085.303724634, ('wyoming', '01JWQ6F1KXK1SBB0NVY8S53WCP'): 267085.304627126}
2025-06-16 12:55:51.058 WARNING (MainThread) [homeassistant.bootstrap] Waiting on integrations to complete setup: {('wyoming', '01JWQ5X3ACXZT0RBZMC38WZ5RP'): 267085.303724634, ('wyoming', '01JWQ6F1KXK1SBB0NVY8S53WCP'): 267085.304627126}
2025-06-16 12:56:51.149 WARNING (MainThread) [homeassistant.bootstrap] Waiting on integrations to complete setup: {('wyoming', '01JWQ5X3ACXZT0RBZMC38WZ5RP'): 267085.303724634, ('wyoming', '01JWQ6F1KXK1SBB0NVY8S53WCP'): 267085.304627126}
2025-06-16 12:57:51.235 WARNING (MainThread) [homeassistant.bootstrap] Waiting on integrations to complete setup: {('wyoming', '01JWQ5X3ACXZT0RBZMC38WZ5RP'): 267085.303724634, ('wyoming', '01JWQ6F1KXK1SBB0NVY8S53WCP'): 267085.304627126}
2025-06-16 12:57:52.888 ERROR (MainThread) [homeassistant.config_entries] Error setting up entry faster-whisper for wyoming
Traceback (most recent call last):
  File "/usr/src/homeassistant/homeassistant/config_entries.py", line 749, in __async_setup_with_context
    result = await component.async_setup_entry(hass, self)
             ^^^^^^^^^^^^^^^^^^^^^^^^^^^^^^^^^^^^^^^^^^^^^
  File "/usr/src/homeassistant/homeassistant/components/wyoming/__init__.py", line 50, in async_setup_entry
    service = await WyomingService.create(entry.data["host"], entry.data["port"])
              ^^^^^^^^^^^^^^^^^^^^^^^^^^^^^^^^^^^^^^^^^^^^^^^^^^^^^^^^^^^^^^^^^^^
  File "/usr/src/homeassistant/homeassistant/components/wyoming/data.py", line 94, in create
    info = await load_wyoming_info(host, port)
           ^^^^^^^^^^^^^^^^^^^^^^^^^^^^^^^^^^^
  File "/usr/src/homeassistant/homeassistant/components/wyoming/data.py", line 113, in load_wyoming_info
    async with AsyncTcpClient(host, port) as client, asyncio.timeout(timeout):
               ~~~~~~~~~~~~~~^^^^^^^^^^^^
  File "/usr/local/lib/python3.13/site-packages/wyoming/client.py", line 35, in __aenter__
    await self.connect()
  File "/usr/local/lib/python3.13/site-packages/wyoming/client.py", line 73, in connect
    self._reader, self._writer = await asyncio.open_connection(
                                 ^^^^^^^^^^^^^^^^^^^^^^^^^^^^^^
    ...<2 lines>...
    )
    ^
  File "/usr/local/lib/python3.13/asyncio/streams.py", line 48, in open_connection
    transport, _ = await loop.create_connection(
                   ^^^^^^^^^^^^^^^^^^^^^^^^^^^^^
        lambda: protocol, host, port, **kwds)
        ^^^^^^^^^^^^^^^^^^^^^^^^^^^^^^^^^^^^^
  File "/usr/local/lib/python3.13/asyncio/base_events.py", line 1135, in create_connection
    sock = await self._connect_sock(
           ^^^^^^^^^^^^^^^^^^^^^^^^^
        exceptions, addrinfo, laddr_infos)
        ^^^^^^^^^^^^^^^^^^^^^^^^^^^^^^^^^^
  File "/usr/local/lib/python3.13/asyncio/base_events.py", line 1038, in _connect_sock
    await self.sock_connect(sock, address)
  File "/usr/local/lib/python3.13/asyncio/selector_events.py", line 641, in sock_connect
    return await fut
           ^^^^^^^^^
asyncio.exceptions.CancelledError: Global task timeout
2025-06-16 12:57:52.900 ERROR (MainThread) [homeassistant.config_entries] Error setting up entry piper for wyoming
Traceback (most recent call last):
  File "/usr/src/homeassistant/homeassistant/config_entries.py", line 749, in __async_setup_with_context
    result = await component.async_setup_entry(hass, self)
             ^^^^^^^^^^^^^^^^^^^^^^^^^^^^^^^^^^^^^^^^^^^^^
  File "/usr/src/homeassistant/homeassistant/components/wyoming/__init__.py", line 50, in async_setup_entry
    service = await WyomingService.create(entry.data["host"], entry.data["port"])
              ^^^^^^^^^^^^^^^^^^^^^^^^^^^^^^^^^^^^^^^^^^^^^^^^^^^^^^^^^^^^^^^^^^^
  File "/usr/src/homeassistant/homeassistant/components/wyoming/data.py", line 94, in create
    info = await load_wyoming_info(host, port)
           ^^^^^^^^^^^^^^^^^^^^^^^^^^^^^^^^^^^
  File "/usr/src/homeassistant/homeassistant/components/wyoming/data.py", line 113, in load_wyoming_info
    async with AsyncTcpClient(host, port) as client, asyncio.timeout(timeout):
               ~~~~~~~~~~~~~~^^^^^^^^^^^^
  File "/usr/local/lib/python3.13/site-packages/wyoming/client.py", line 35, in __aenter__
    await self.connect()
  File "/usr/local/lib/python3.13/site-packages/wyoming/client.py", line 73, in connect
    self._reader, self._writer = await asyncio.open_connection(
                                 ^^^^^^^^^^^^^^^^^^^^^^^^^^^^^^
    ...<2 lines>...
    )
    ^
  File "/usr/local/lib/python3.13/asyncio/streams.py", line 48, in open_connection
    transport, _ = await loop.create_connection(
                   ^^^^^^^^^^^^^^^^^^^^^^^^^^^^^
        lambda: protocol, host, port, **kwds)
        ^^^^^^^^^^^^^^^^^^^^^^^^^^^^^^^^^^^^^
  File "/usr/local/lib/python3.13/asyncio/base_events.py", line 1135, in create_connection
    sock = await self._connect_sock(
           ^^^^^^^^^^^^^^^^^^^^^^^^^
        exceptions, addrinfo, laddr_infos)
        ^^^^^^^^^^^^^^^^^^^^^^^^^^^^^^^^^^
  File "/usr/local/lib/python3.13/asyncio/base_events.py", line 1038, in _connect_sock
    await self.sock_connect(sock, address)
  File "/usr/local/lib/python3.13/asyncio/selector_events.py", line 641, in sock_connect
    return await fut
           ^^^^^^^^^
asyncio.exceptions.CancelledError: Global task timeout
2025-06-16 12:57:52.902 WARNING (MainThread) [homeassistant.bootstrap] Setup timed out for stage 2 waiting on set() - moving forward
